Fri Oct 14 22:50:02 2022
Traceback (most recent call last):
  File "C:\Users\gallo\Code\Programmi\FoxHoleApi\main.py", line 69, in background_task
    message, color = switch(map, newData[i]['teamId'], oldData[j]['teamId'], i, newData[i]['flags'])
  File "C:\Users\gallo\Code\Programmi\FoxHoleApi\main.py", line 177, in switch
    return msg[0].format(' è stato conquistato dai Wardens'), 0
IndexError: Replacement index 1 out of range for positional args tuple

Fri Oct 14 23:08:23 2022
Traceback (most recent call last):
  File "C:\Users\gallo\AppData\Local\Programs\Python\Python39\lib\asyncio\runners.py", line 44, in run
    return loop.run_until_complete(main)
  File "C:\Users\gallo\AppData\Local\Programs\Python\Python39\lib\asyncio\base_events.py", line 629, in run_until_complete
    self.run_forever()
  File "C:\Users\gallo\AppData\Local\Programs\Python\Python39\lib\asyncio\windows_events.py", line 316, in run_forever
    super().run_forever()
  File "C:\Users\gallo\AppData\Local\Programs\Python\Python39\lib\asyncio\base_events.py", line 596, in run_forever
    self._run_once()
  File "C:\Users\gallo\AppData\Local\Programs\Python\Python39\lib\asyncio\base_events.py", line 1854, in _run_once
    event_list = self._selector.select(timeout)
  File "C:\Users\gallo\AppData\Local\Programs\Python\Python39\lib\asyncio\windows_events.py", line 434, in select
    self._poll(timeout)
  File "C:\Users\gallo\AppData\Local\Programs\Python\Python39\lib\asyncio\windows_events.py", line 783, in _poll
    status = _overlapped.GetQueuedCompletionStatus(self._iocp, ms)
KeyboardInterrupt

During handling of the above exception, another exception occurred:

Traceback (most recent call last):
  File "C:\Users\gallo\Code\Programmi\FoxHoleApi\main.py", line 94, in background_task
    await asyncio.sleep(1)
  File "C:\Users\gallo\AppData\Local\Programs\Python\Python39\lib\asyncio\tasks.py", line 649, in sleep
    return await future
asyncio.exceptions.CancelledError

Fri Oct 14 23:09:07 2022
Traceback (most recent call last):
  File "C:\Users\gallo\Code\Programmi\FoxHoleApi\main.py", line 39, in background_task
    data = downloadData(map, 1)
  File "C:\Users\gallo\Code\Programmi\FoxHoleApi\testRequest.py", line 29, in downloadData
    data = requests.get(url[1].format(map)).json()
  File "C:\Users\gallo\AppData\Local\Programs\Python\Python39\lib\site-packages\requests\api.py", line 76, in get
    return request('get', url, params=params, **kwargs)
  File "C:\Users\gallo\AppData\Local\Programs\Python\Python39\lib\site-packages\requests\api.py", line 61, in request
    return session.request(method=method, url=url, **kwargs)
  File "C:\Users\gallo\AppData\Local\Programs\Python\Python39\lib\site-packages\requests\sessions.py", line 542, in request
    resp = self.send(prep, **send_kwargs)
  File "C:\Users\gallo\AppData\Local\Programs\Python\Python39\lib\site-packages\requests\sessions.py", line 655, in send
    r = adapter.send(request, **kwargs)
  File "C:\Users\gallo\AppData\Local\Programs\Python\Python39\lib\site-packages\requests\adapters.py", line 439, in send
    resp = conn.urlopen(
  File "C:\Users\gallo\AppData\Local\Programs\Python\Python39\lib\site-packages\urllib3\connectionpool.py", line 699, in urlopen
    httplib_response = self._make_request(
  File "C:\Users\gallo\AppData\Local\Programs\Python\Python39\lib\site-packages\urllib3\connectionpool.py", line 382, in _make_request
    self._validate_conn(conn)
  File "C:\Users\gallo\AppData\Local\Programs\Python\Python39\lib\site-packages\urllib3\connectionpool.py", line 1010, in _validate_conn
    conn.connect()
  File "C:\Users\gallo\AppData\Local\Programs\Python\Python39\lib\site-packages\urllib3\connection.py", line 411, in connect
    self.sock = ssl_wrap_socket(
  File "C:\Users\gallo\AppData\Local\Programs\Python\Python39\lib\site-packages\urllib3\util\ssl_.py", line 428, in ssl_wrap_socket
    ssl_sock = _ssl_wrap_socket_impl(
  File "C:\Users\gallo\AppData\Local\Programs\Python\Python39\lib\site-packages\urllib3\util\ssl_.py", line 472, in _ssl_wrap_socket_impl
    return ssl_context.wrap_socket(sock, server_hostname=server_hostname)
  File "C:\Users\gallo\AppData\Local\Programs\Python\Python39\lib\ssl.py", line 500, in wrap_socket
    return self.sslsocket_class._create(
  File "C:\Users\gallo\AppData\Local\Programs\Python\Python39\lib\ssl.py", line 1040, in _create
    self.do_handshake()
  File "C:\Users\gallo\AppData\Local\Programs\Python\Python39\lib\ssl.py", line 1309, in do_handshake
    self._sslobj.do_handshake()
KeyboardInterrupt

Sat Oct 15 17:31:23 2022
Traceback (most recent call last):
  File "C:\Users\gallo\Code\Programmi\FoxHoleApi\main.py", line 177, in switch
    return msg[1].format(' è stato conquistato dai Colonials'), 1
IndexError: Replacement index 1 out of range for positional args tuple

Sat Oct 15 17:31:23 2022
Traceback (most recent call last):
  File "C:\Users\gallo\Code\Programmi\FoxHoleApi\main.py", line 69, in background_task
    message, color = switch(map, newData[i]['teamId'], oldData[j]['teamId'], i, newData[i]['flags'])
TypeError: cannot unpack non-iterable NoneType object

Sat Oct 15 17:36:07 2022
Traceback (most recent call last):
  File "C:\Users\gallo\AppData\Local\Programs\Python\Python39\lib\asyncio\runners.py", line 44, in run
    return loop.run_until_complete(main)
  File "C:\Users\gallo\AppData\Local\Programs\Python\Python39\lib\asyncio\base_events.py", line 629, in run_until_complete
    self.run_forever()
  File "C:\Users\gallo\AppData\Local\Programs\Python\Python39\lib\asyncio\windows_events.py", line 316, in run_forever
    super().run_forever()
  File "C:\Users\gallo\AppData\Local\Programs\Python\Python39\lib\asyncio\base_events.py", line 596, in run_forever
    self._run_once()
  File "C:\Users\gallo\AppData\Local\Programs\Python\Python39\lib\asyncio\base_events.py", line 1854, in _run_once
    event_list = self._selector.select(timeout)
  File "C:\Users\gallo\AppData\Local\Programs\Python\Python39\lib\asyncio\windows_events.py", line 434, in select
    self._poll(timeout)
  File "C:\Users\gallo\AppData\Local\Programs\Python\Python39\lib\asyncio\windows_events.py", line 783, in _poll
    status = _overlapped.GetQueuedCompletionStatus(self._iocp, ms)
KeyboardInterrupt

During handling of the above exception, another exception occurred:

Traceback (most recent call last):
  File "C:\Users\gallo\Code\Programmi\FoxHoleApi\main.py", line 94, in background_task
    await asyncio.sleep(1)
  File "C:\Users\gallo\AppData\Local\Programs\Python\Python39\lib\asyncio\tasks.py", line 649, in sleep
    return await future
asyncio.exceptions.CancelledError

Sat Oct 15 17:37:42 2022
Traceback (most recent call last):
  File "C:\Users\gallo\AppData\Local\Programs\Python\Python39\lib\asyncio\runners.py", line 44, in run
    return loop.run_until_complete(main)
  File "C:\Users\gallo\AppData\Local\Programs\Python\Python39\lib\asyncio\base_events.py", line 629, in run_until_complete
    self.run_forever()
  File "C:\Users\gallo\AppData\Local\Programs\Python\Python39\lib\asyncio\windows_events.py", line 316, in run_forever
    super().run_forever()
  File "C:\Users\gallo\AppData\Local\Programs\Python\Python39\lib\asyncio\base_events.py", line 596, in run_forever
    self._run_once()
  File "C:\Users\gallo\AppData\Local\Programs\Python\Python39\lib\asyncio\base_events.py", line 1854, in _run_once
    event_list = self._selector.select(timeout)
  File "C:\Users\gallo\AppData\Local\Programs\Python\Python39\lib\asyncio\windows_events.py", line 434, in select
    self._poll(timeout)
  File "C:\Users\gallo\AppData\Local\Programs\Python\Python39\lib\asyncio\windows_events.py", line 783, in _poll
    status = _overlapped.GetQueuedCompletionStatus(self._iocp, ms)
KeyboardInterrupt

During handling of the above exception, another exception occurred:

Traceback (most recent call last):
  File "C:\Users\gallo\Code\Programmi\FoxHoleApi\main.py", line 94, in background_task
    await asyncio.sleep(1)
  File "C:\Users\gallo\AppData\Local\Programs\Python\Python39\lib\asyncio\tasks.py", line 649, in sleep
    return await future
asyncio.exceptions.CancelledError

Sat Oct 15 17:40:42 2022
Traceback (most recent call last):
  File "C:\Users\gallo\AppData\Local\Programs\Python\Python39\lib\asyncio\runners.py", line 44, in run
    return loop.run_until_complete(main)
  File "C:\Users\gallo\AppData\Local\Programs\Python\Python39\lib\asyncio\base_events.py", line 629, in run_until_complete
    self.run_forever()
  File "C:\Users\gallo\AppData\Local\Programs\Python\Python39\lib\asyncio\windows_events.py", line 316, in run_forever
    super().run_forever()
  File "C:\Users\gallo\AppData\Local\Programs\Python\Python39\lib\asyncio\base_events.py", line 596, in run_forever
    self._run_once()
  File "C:\Users\gallo\AppData\Local\Programs\Python\Python39\lib\asyncio\base_events.py", line 1854, in _run_once
    event_list = self._selector.select(timeout)
  File "C:\Users\gallo\AppData\Local\Programs\Python\Python39\lib\asyncio\windows_events.py", line 434, in select
    self._poll(timeout)
  File "C:\Users\gallo\AppData\Local\Programs\Python\Python39\lib\asyncio\windows_events.py", line 783, in _poll
    status = _overlapped.GetQueuedCompletionStatus(self._iocp, ms)
KeyboardInterrupt

During handling of the above exception, another exception occurred:

Traceback (most recent call last):
  File "C:\Users\gallo\Code\Programmi\FoxHoleApi\main.py", line 94, in background_task
    await asyncio.sleep(1)
  File "C:\Users\gallo\AppData\Local\Programs\Python\Python39\lib\asyncio\tasks.py", line 649, in sleep
    return await future
asyncio.exceptions.CancelledError

Sat Oct 15 17:59:54 2022
Traceback (most recent call last):
  File "C:\Users\gallo\Code\Programmi\FoxHoleApi\main.py", line 38, in background_task
    data = downloadData(map, 1)
  File "C:\Users\gallo\Code\Programmi\FoxHoleApi\testRequest.py", line 29, in downloadData
    data = requests.get(url[1].format(map)).json()
  File "C:\Users\gallo\AppData\Local\Programs\Python\Python39\lib\site-packages\requests\api.py", line 76, in get
    return request('get', url, params=params, **kwargs)
  File "C:\Users\gallo\AppData\Local\Programs\Python\Python39\lib\site-packages\requests\api.py", line 61, in request
    return session.request(method=method, url=url, **kwargs)
  File "C:\Users\gallo\AppData\Local\Programs\Python\Python39\lib\site-packages\requests\sessions.py", line 542, in request
    resp = self.send(prep, **send_kwargs)
  File "C:\Users\gallo\AppData\Local\Programs\Python\Python39\lib\site-packages\requests\sessions.py", line 655, in send
    r = adapter.send(request, **kwargs)
  File "C:\Users\gallo\AppData\Local\Programs\Python\Python39\lib\site-packages\requests\adapters.py", line 439, in send
    resp = conn.urlopen(
  File "C:\Users\gallo\AppData\Local\Programs\Python\Python39\lib\site-packages\urllib3\connectionpool.py", line 699, in urlopen
    httplib_response = self._make_request(
  File "C:\Users\gallo\AppData\Local\Programs\Python\Python39\lib\site-packages\urllib3\connectionpool.py", line 445, in _make_request
    six.raise_from(e, None)
  File "<string>", line 3, in raise_from
  File "C:\Users\gallo\AppData\Local\Programs\Python\Python39\lib\site-packages\urllib3\connectionpool.py", line 440, in _make_request
    httplib_response = conn.getresponse()
  File "C:\Users\gallo\AppData\Local\Programs\Python\Python39\lib\http\client.py", line 1347, in getresponse
    response.begin()
  File "C:\Users\gallo\AppData\Local\Programs\Python\Python39\lib\http\client.py", line 307, in begin
    version, status, reason = self._read_status()
  File "C:\Users\gallo\AppData\Local\Programs\Python\Python39\lib\http\client.py", line 268, in _read_status
    line = str(self.fp.readline(_MAXLINE + 1), "iso-8859-1")
  File "C:\Users\gallo\AppData\Local\Programs\Python\Python39\lib\socket.py", line 704, in readinto
    return self._sock.recv_into(b)
  File "C:\Users\gallo\AppData\Local\Programs\Python\Python39\lib\ssl.py", line 1241, in recv_into
    return self.read(nbytes, buffer)
  File "C:\Users\gallo\AppData\Local\Programs\Python\Python39\lib\ssl.py", line 1099, in read
    return self._sslobj.read(len, buffer)
KeyboardInterrupt

Sat Oct 15 18:00:17 2022
Traceback (most recent call last):
  File "C:\Users\gallo\AppData\Local\Programs\Python\Python39\lib\asyncio\runners.py", line 44, in run
    return loop.run_until_complete(main)
  File "C:\Users\gallo\AppData\Local\Programs\Python\Python39\lib\asyncio\base_events.py", line 629, in run_until_complete
    self.run_forever()
  File "C:\Users\gallo\AppData\Local\Programs\Python\Python39\lib\asyncio\windows_events.py", line 316, in run_forever
    super().run_forever()
  File "C:\Users\gallo\AppData\Local\Programs\Python\Python39\lib\asyncio\base_events.py", line 596, in run_forever
    self._run_once()
  File "C:\Users\gallo\AppData\Local\Programs\Python\Python39\lib\asyncio\base_events.py", line 1854, in _run_once
    event_list = self._selector.select(timeout)
  File "C:\Users\gallo\AppData\Local\Programs\Python\Python39\lib\asyncio\windows_events.py", line 434, in select
    self._poll(timeout)
  File "C:\Users\gallo\AppData\Local\Programs\Python\Python39\lib\asyncio\windows_events.py", line 783, in _poll
    status = _overlapped.GetQueuedCompletionStatus(self._iocp, ms)
KeyboardInterrupt

During handling of the above exception, another exception occurred:

Traceback (most recent call last):
  File "C:\Users\gallo\Code\Programmi\FoxHoleApi\main.py", line 93, in background_task
    await asyncio.sleep(1)
  File "C:\Users\gallo\AppData\Local\Programs\Python\Python39\lib\asyncio\tasks.py", line 649, in sleep
    return await future
asyncio.exceptions.CancelledError

Sat Oct 15 18:14:24 2022
Traceback (most recent call last):
  File "C:\Users\gallo\Code\Programmi\FoxHoleApi\main.py", line 38, in background_task
    data = downloadData(map, 1)
  File "C:\Users\gallo\Code\Programmi\FoxHoleApi\testRequest.py", line 29, in downloadData
    data = requests.get(url[1].format(map)).json()
  File "C:\Users\gallo\AppData\Local\Programs\Python\Python39\lib\site-packages\requests\api.py", line 76, in get
    return request('get', url, params=params, **kwargs)
  File "C:\Users\gallo\AppData\Local\Programs\Python\Python39\lib\site-packages\requests\api.py", line 61, in request
    return session.request(method=method, url=url, **kwargs)
  File "C:\Users\gallo\AppData\Local\Programs\Python\Python39\lib\site-packages\requests\sessions.py", line 542, in request
    resp = self.send(prep, **send_kwargs)
  File "C:\Users\gallo\AppData\Local\Programs\Python\Python39\lib\site-packages\requests\sessions.py", line 655, in send
    r = adapter.send(request, **kwargs)
  File "C:\Users\gallo\AppData\Local\Programs\Python\Python39\lib\site-packages\requests\adapters.py", line 439, in send
    resp = conn.urlopen(
  File "C:\Users\gallo\AppData\Local\Programs\Python\Python39\lib\site-packages\urllib3\connectionpool.py", line 699, in urlopen
    httplib_response = self._make_request(
  File "C:\Users\gallo\AppData\Local\Programs\Python\Python39\lib\site-packages\urllib3\connectionpool.py", line 382, in _make_request
    self._validate_conn(conn)
  File "C:\Users\gallo\AppData\Local\Programs\Python\Python39\lib\site-packages\urllib3\connectionpool.py", line 1010, in _validate_conn
    conn.connect()
  File "C:\Users\gallo\AppData\Local\Programs\Python\Python39\lib\site-packages\urllib3\connection.py", line 411, in connect
    self.sock = ssl_wrap_socket(
  File "C:\Users\gallo\AppData\Local\Programs\Python\Python39\lib\site-packages\urllib3\util\ssl_.py", line 428, in ssl_wrap_socket
    ssl_sock = _ssl_wrap_socket_impl(
  File "C:\Users\gallo\AppData\Local\Programs\Python\Python39\lib\site-packages\urllib3\util\ssl_.py", line 472, in _ssl_wrap_socket_impl
    return ssl_context.wrap_socket(sock, server_hostname=server_hostname)
  File "C:\Users\gallo\AppData\Local\Programs\Python\Python39\lib\ssl.py", line 500, in wrap_socket
    return self.sslsocket_class._create(
  File "C:\Users\gallo\AppData\Local\Programs\Python\Python39\lib\ssl.py", line 1040, in _create
    self.do_handshake()
  File "C:\Users\gallo\AppData\Local\Programs\Python\Python39\lib\ssl.py", line 1309, in do_handshake
    self._sslobj.do_handshake()
KeyboardInterrupt

Sun Oct 16 20:37:00 2022
Traceback (most recent call last):
  File "C:\Users\gallo\Code\Programmi\FoxHoleApi\main.py", line 40, in background_task
    oldData = read(defs.DB['mapData'].format(map))
  File "C:\Users\gallo\Code\Programmi\FoxHoleApi\testRequest.py", line 77, in read
    with open(path, 'r') as f:
FileNotFoundError: [Errno 2] No such file or directory: '/app/data/MapData/TheFingers.json'

Sun Oct 16 20:37:11 2022
Traceback (most recent call last):
  File "C:\Users\gallo\Code\Programmi\FoxHoleApi\main.py", line 40, in background_task
    oldData = read(defs.DB['mapData'].format(map))
  File "C:\Users\gallo\Code\Programmi\FoxHoleApi\testRequest.py", line 77, in read
    with open(path, 'r') as f:
FileNotFoundError: [Errno 2] No such file or directory: '/app/data/MapData/TheFingers.json'

Sun Oct 16 20:37:23 2022
Traceback (most recent call last):
  File "C:\Users\gallo\Code\Programmi\FoxHoleApi\main.py", line 40, in background_task
    oldData = read(defs.DB['mapData'].format(map))
  File "C:\Users\gallo\Code\Programmi\FoxHoleApi\testRequest.py", line 77, in read
    with open(path, 'r') as f:
FileNotFoundError: [Errno 2] No such file or directory: '/app/data/MapData/TheFingers.json'

Sun Oct 16 20:37:50 2022
Traceback (most recent call last):
  File "C:\Users\gallo\Code\Programmi\FoxHoleApi\main.py", line 40, in background_task
    oldData = read(defs.DB['mapData'].format(map))
  File "C:\Users\gallo\Code\Programmi\FoxHoleApi\testRequest.py", line 77, in read
    with open(path, 'r') as f:
FileNotFoundError: [Errno 2] No such file or directory: '/data/MapData/TheFingers.json'

Sun Oct 16 20:38:02 2022
Traceback (most recent call last):
  File "C:\Users\gallo\Code\Programmi\FoxHoleApi\main.py", line 40, in background_task
    oldData = read(defs.DB['mapData'].format(map))
  File "C:\Users\gallo\Code\Programmi\FoxHoleApi\testRequest.py", line 77, in read
    with open(path, 'r') as f:
FileNotFoundError: [Errno 2] No such file or directory: '/data/MapData/TheFingers.json'

Sun Oct 16 20:38:14 2022
Traceback (most recent call last):
  File "C:\Users\gallo\Code\Programmi\FoxHoleApi\main.py", line 40, in background_task
    oldData = read(defs.DB['mapData'].format(map))
  File "C:\Users\gallo\Code\Programmi\FoxHoleApi\testRequest.py", line 77, in read
    with open(path, 'r') as f:
FileNotFoundError: [Errno 2] No such file or directory: '/data/MapData/TheFingers.json'

Sun Oct 16 20:38:26 2022
Traceback (most recent call last):
  File "C:\Users\gallo\Code\Programmi\FoxHoleApi\main.py", line 40, in background_task
    oldData = read(defs.DB['mapData'].format(map))
  File "C:\Users\gallo\Code\Programmi\FoxHoleApi\testRequest.py", line 77, in read
    with open(path, 'r') as f:
FileNotFoundError: [Errno 2] No such file or directory: '/data/MapData/TheFingers.json'

Sun Oct 16 20:38:39 2022
Traceback (most recent call last):
  File "C:\Users\gallo\Code\Programmi\FoxHoleApi\main.py", line 40, in background_task
    oldData = read(defs.DB['mapData'].format(map))
  File "C:\Users\gallo\Code\Programmi\FoxHoleApi\testRequest.py", line 77, in read
    with open(path, 'r') as f:
FileNotFoundError: [Errno 2] No such file or directory: '/data/MapData/TheFingers.json'

Sun Oct 16 20:38:51 2022
Traceback (most recent call last):
  File "C:\Users\gallo\Code\Programmi\FoxHoleApi\main.py", line 40, in background_task
    oldData = read(defs.DB['mapData'].format(map))
  File "C:\Users\gallo\Code\Programmi\FoxHoleApi\testRequest.py", line 77, in read
    with open(path, 'r') as f:
FileNotFoundError: [Errno 2] No such file or directory: '/data/MapData/TheFingers.json'

Sun Oct 16 20:39:03 2022
Traceback (most recent call last):
  File "C:\Users\gallo\Code\Programmi\FoxHoleApi\main.py", line 40, in background_task
    oldData = read(defs.DB['mapData'].format(map))
  File "C:\Users\gallo\Code\Programmi\FoxHoleApi\testRequest.py", line 77, in read
    with open(path, 'r') as f:
FileNotFoundError: [Errno 2] No such file or directory: '/data/MapData/TheFingers.json'

Sun Oct 16 20:39:14 2022
Traceback (most recent call last):
  File "C:\Users\gallo\Code\Programmi\FoxHoleApi\main.py", line 40, in background_task
    oldData = read(defs.DB['mapData'].format(map))
  File "C:\Users\gallo\Code\Programmi\FoxHoleApi\testRequest.py", line 77, in read
    with open(path, 'r') as f:
FileNotFoundError: [Errno 2] No such file or directory: '/data/MapData/TheFingers.json'

Sun Oct 16 20:41:48 2022
Traceback (most recent call last):
  File "C:\Users\gallo\AppData\Local\Programs\Python\Python39\lib\asyncio\runners.py", line 44, in run
    return loop.run_until_complete(main)
  File "C:\Users\gallo\AppData\Local\Programs\Python\Python39\lib\asyncio\base_events.py", line 629, in run_until_complete
    self.run_forever()
  File "C:\Users\gallo\AppData\Local\Programs\Python\Python39\lib\asyncio\windows_events.py", line 316, in run_forever
    super().run_forever()
  File "C:\Users\gallo\AppData\Local\Programs\Python\Python39\lib\asyncio\base_events.py", line 596, in run_forever
    self._run_once()
  File "C:\Users\gallo\AppData\Local\Programs\Python\Python39\lib\asyncio\base_events.py", line 1854, in _run_once
    event_list = self._selector.select(timeout)
  File "C:\Users\gallo\AppData\Local\Programs\Python\Python39\lib\asyncio\windows_events.py", line 434, in select
    self._poll(timeout)
  File "C:\Users\gallo\AppData\Local\Programs\Python\Python39\lib\asyncio\windows_events.py", line 783, in _poll
    status = _overlapped.GetQueuedCompletionStatus(self._iocp, ms)
KeyboardInterrupt

During handling of the above exception, another exception occurred:

Traceback (most recent call last):
  File "C:\Users\gallo\Code\Programmi\FoxHoleApi\main.py", line 91, in background_task
    await channel.send(files = [fileMap, fileIcon], embed=embed)
  File "C:\Users\gallo\AppData\Local\Programs\Python\Python39\lib\site-packages\discord\abc.py", line 1536, in send
    data = await state.http.send_message(channel.id, params=params)
  File "C:\Users\gallo\AppData\Local\Programs\Python\Python39\lib\site-packages\discord\http.py", line 624, in request
    async with self.__session.request(method, url, **kwargs) as response:
  File "C:\Users\gallo\AppData\Local\Programs\Python\Python39\lib\site-packages\aiohttp\client.py", line 1117, in __aenter__
    self._resp = await self._coro
  File "C:\Users\gallo\AppData\Local\Programs\Python\Python39\lib\site-packages\aiohttp\client.py", line 544, in _request
    await resp.start(conn)
  File "C:\Users\gallo\AppData\Local\Programs\Python\Python39\lib\site-packages\aiohttp\client_reqrep.py", line 890, in start
    message, payload = await self._protocol.read()  # type: ignore
  File "C:\Users\gallo\AppData\Local\Programs\Python\Python39\lib\site-packages\aiohttp\streams.py", line 604, in read
    await self._waiter
asyncio.exceptions.CancelledError

Sun Oct 16 20:42:20 2022
Traceback (most recent call last):
  File "C:\Users\gallo\AppData\Local\Programs\Python\Python39\lib\asyncio\runners.py", line 44, in run
    return loop.run_until_complete(main)
  File "C:\Users\gallo\AppData\Local\Programs\Python\Python39\lib\asyncio\base_events.py", line 629, in run_until_complete
    self.run_forever()
  File "C:\Users\gallo\AppData\Local\Programs\Python\Python39\lib\asyncio\windows_events.py", line 316, in run_forever
    super().run_forever()
  File "C:\Users\gallo\AppData\Local\Programs\Python\Python39\lib\asyncio\base_events.py", line 596, in run_forever
    self._run_once()
  File "C:\Users\gallo\AppData\Local\Programs\Python\Python39\lib\asyncio\base_events.py", line 1854, in _run_once
    event_list = self._selector.select(timeout)
  File "C:\Users\gallo\AppData\Local\Programs\Python\Python39\lib\asyncio\windows_events.py", line 434, in select
    self._poll(timeout)
  File "C:\Users\gallo\AppData\Local\Programs\Python\Python39\lib\asyncio\windows_events.py", line 783, in _poll
    status = _overlapped.GetQueuedCompletionStatus(self._iocp, ms)
KeyboardInterrupt

During handling of the above exception, another exception occurred:

Traceback (most recent call last):
  File "C:\Users\gallo\Code\Programmi\FoxHoleApi\main.py", line 91, in background_task
    await channel.send(files = [fileMap, fileIcon], embed=embed)
  File "C:\Users\gallo\AppData\Local\Programs\Python\Python39\lib\site-packages\discord\abc.py", line 1536, in send
    data = await state.http.send_message(channel.id, params=params)
  File "C:\Users\gallo\AppData\Local\Programs\Python\Python39\lib\site-packages\discord\http.py", line 624, in request
    async with self.__session.request(method, url, **kwargs) as response:
  File "C:\Users\gallo\AppData\Local\Programs\Python\Python39\lib\site-packages\aiohttp\client.py", line 1117, in __aenter__
    self._resp = await self._coro
  File "C:\Users\gallo\AppData\Local\Programs\Python\Python39\lib\site-packages\aiohttp\client.py", line 381, in _request
    raise RuntimeError("Session is closed")
RuntimeError: Session is closed

Sun Oct 16 23:15:12 2022
Traceback (most recent call last):
  File "C:\Users\gallo\Code\Programmi\FoxHoleApi\main.py", line 173, in switch
    return msg[1].format(' è stato distrutto dai Colonials'), 1
IndexError: Replacement index 1 out of range for positional args tuple

During handling of the above exception, another exception occurred:

Traceback (most recent call last):
  File "C:\Users\gallo\Code\Programmi\FoxHoleApi\main.py", line 68, in background_task
    message, color = switch(map, newData[i]['teamId'], oldData[j]['teamId'], i, newData[i]['flags'])
  File "C:\Users\gallo\Code\Programmi\FoxHoleApi\main.py", line 180, in switch
    print(time.asctime(time.localtime(time.time())) + '\n' + traceback.format_exc() + '\n' + msg + '\n')
TypeError: can only concatenate str (not "list") to str

Sun Oct 16 23:15:38 2022
Traceback (most recent call last):
  File "C:\Users\gallo\Code\Programmi\FoxHoleApi\main.py", line 171, in switch
    return msg[0].format(' è stato distrutto dai Wardens'), 0
IndexError: Replacement index 1 out of range for positional args tuple

During handling of the above exception, another exception occurred:

Traceback (most recent call last):
  File "C:\Users\gallo\Code\Programmi\FoxHoleApi\main.py", line 68, in background_task
    message, color = switch(map, newData[i]['teamId'], oldData[j]['teamId'], i, newData[i]['flags'])
  File "C:\Users\gallo\Code\Programmi\FoxHoleApi\main.py", line 180, in switch
    print(time.asctime(time.localtime(time.time())) + '\n' + traceback.format_exc() + '\n' + msg + '\n')
TypeError: can only concatenate str (not "list") to str

Sun Oct 16 23:16:25 2022
Traceback (most recent call last):
  File "C:\Users\gallo\Code\Programmi\FoxHoleApi\main.py", line 171, in switch
    return msg[0].format(' è stato distrutto dai Wardens'), 0
IndexError: Replacement index 1 out of range for positional args tuple

During handling of the above exception, another exception occurred:

Traceback (most recent call last):
  File "C:\Users\gallo\Code\Programmi\FoxHoleApi\main.py", line 68, in background_task
    message, color = switch(map, newData[i]['teamId'], oldData[j]['teamId'], i, newData[i]['flags'])
  File "C:\Users\gallo\Code\Programmi\FoxHoleApi\main.py", line 180, in switch
    print(time.asctime(time.localtime(time.time())) + '\n' + traceback.format_exc() + '\n' + msg + '\n')
TypeError: can only concatenate str (not "list") to str

Sun Oct 16 23:19:01 2022
Traceback (most recent call last):
  File "C:\Users\gallo\Code\Programmi\FoxHoleApi\main.py", line 171, in switch
    return msg[0].format(' è stato distrutto dai Wardens'), 0
IndexError: Replacement index 1 out of range for positional args tuple

During handling of the above exception, another exception occurred:

Traceback (most recent call last):
  File "C:\Users\gallo\Code\Programmi\FoxHoleApi\main.py", line 68, in background_task
    message, color = switch(map, newData[i]['teamId'], oldData[j]['teamId'], i, newData[i]['flags'])
  File "C:\Users\gallo\Code\Programmi\FoxHoleApi\main.py", line 180, in switch
    print(time.asctime(time.localtime(time.time())) + '\n' + traceback.format_exc() + '\n' + msg + '\n')
TypeError: can only concatenate str (not "list") to str

Sun Oct 16 23:23:38 2022
Traceback (most recent call last):
  File "C:\Users\gallo\Code\Programmi\FoxHoleApi\main.py", line 171, in switch
    return msg[0].format(' è stato distrutto dai Wardens'), 0
IndexError: Replacement index 1 out of range for positional args tuple

During handling of the above exception, another exception occurred:

Traceback (most recent call last):
  File "C:\Users\gallo\Code\Programmi\FoxHoleApi\main.py", line 68, in background_task
    message, color = switch(map, newData[i]['teamId'], oldData[j]['teamId'], i, newData[i]['flags'])
  File "C:\Users\gallo\Code\Programmi\FoxHoleApi\main.py", line 180, in switch
    print(time.asctime(time.localtime(time.time())) + '\n' + traceback.format_exc() + '\n' + msg + '\n')
TypeError: can only concatenate str (not "list") to str

Sun Oct 16 23:35:50 2022
Traceback (most recent call last):
  File "C:\Users\gallo\Code\Programmi\FoxHoleApi\main.py", line 173, in switch
    return msg[1].format(' è stato distrutto dai Colonials'), 1
IndexError: Replacement index 1 out of range for positional args tuple

During handling of the above exception, another exception occurred:

Traceback (most recent call last):
  File "C:\Users\gallo\Code\Programmi\FoxHoleApi\main.py", line 68, in background_task
    message, color = switch(map, newData[i]['teamId'], oldData[j]['teamId'], i, newData[i]['flags'])
  File "C:\Users\gallo\Code\Programmi\FoxHoleApi\main.py", line 180, in switch
    print(time.asctime(time.localtime(time.time())) + '\n' + traceback.format_exc() + '\n' + msg + '\n')
TypeError: can only concatenate str (not "list") to str

Mon Oct 17 10:28:02 2022
Traceback (most recent call last):
  File "C:\Users\gallo\AppData\Local\Programs\Python\Python39\lib\asyncio\runners.py", line 44, in run
    return loop.run_until_complete(main)
  File "C:\Users\gallo\AppData\Local\Programs\Python\Python39\lib\asyncio\base_events.py", line 629, in run_until_complete
    self.run_forever()
  File "C:\Users\gallo\AppData\Local\Programs\Python\Python39\lib\asyncio\windows_events.py", line 316, in run_forever
    super().run_forever()
  File "C:\Users\gallo\AppData\Local\Programs\Python\Python39\lib\asyncio\base_events.py", line 596, in run_forever
    self._run_once()
  File "C:\Users\gallo\AppData\Local\Programs\Python\Python39\lib\asyncio\base_events.py", line 1854, in _run_once
    event_list = self._selector.select(timeout)
  File "C:\Users\gallo\AppData\Local\Programs\Python\Python39\lib\asyncio\windows_events.py", line 434, in select
    self._poll(timeout)
  File "C:\Users\gallo\AppData\Local\Programs\Python\Python39\lib\asyncio\windows_events.py", line 783, in _poll
    status = _overlapped.GetQueuedCompletionStatus(self._iocp, ms)
KeyboardInterrupt

During handling of the above exception, another exception occurred:

Traceback (most recent call last):
  File "c:\Users\gallo\Code\Programmi\FoxholeApi\main.py", line 94, in background_task
    await asyncio.sleep(1)
  File "C:\Users\gallo\AppData\Local\Programs\Python\Python39\lib\asyncio\tasks.py", line 649, in sleep
    return await future
asyncio.exceptions.CancelledError

Mon Oct 17 10:38:25 2022
Traceback (most recent call last):
  File "c:\Users\gallo\Code\Programmi\FoxholeApi\main.py", line 38, in background_task
    data = downloadData(map, 1)
  File "c:\Users\gallo\Code\Programmi\FoxholeApi\testRequest.py", line 29, in downloadData
    data = requests.get(url[1].format(map)).json()
  File "C:\Users\gallo\AppData\Local\Programs\Python\Python39\lib\site-packages\requests\api.py", line 73, in get
    return request("get", url, params=params, **kwargs)
  File "C:\Users\gallo\AppData\Local\Programs\Python\Python39\lib\site-packages\requests\api.py", line 59, in request
    return session.request(method=method, url=url, **kwargs)
  File "C:\Users\gallo\AppData\Local\Programs\Python\Python39\lib\site-packages\requests\sessions.py", line 587, in request
    resp = self.send(prep, **send_kwargs)
  File "C:\Users\gallo\AppData\Local\Programs\Python\Python39\lib\site-packages\requests\sessions.py", line 701, in send
    r = adapter.send(request, **kwargs)
  File "C:\Users\gallo\AppData\Local\Programs\Python\Python39\lib\site-packages\requests\adapters.py", line 489, in send
    resp = conn.urlopen(
  File "C:\Users\gallo\AppData\Local\Programs\Python\Python39\lib\site-packages\urllib3\connectionpool.py", line 699, in urlopen
    httplib_response = self._make_request(
  File "C:\Users\gallo\AppData\Local\Programs\Python\Python39\lib\site-packages\urllib3\connectionpool.py", line 382, in _make_request
    self._validate_conn(conn)
  File "C:\Users\gallo\AppData\Local\Programs\Python\Python39\lib\site-packages\urllib3\connectionpool.py", line 1010, in _validate_conn
    conn.connect()
  File "C:\Users\gallo\AppData\Local\Programs\Python\Python39\lib\site-packages\urllib3\connection.py", line 411, in connect
    self.sock = ssl_wrap_socket(
  File "C:\Users\gallo\AppData\Local\Programs\Python\Python39\lib\site-packages\urllib3\util\ssl_.py", line 428, in ssl_wrap_socket
    ssl_sock = _ssl_wrap_socket_impl(
  File "C:\Users\gallo\AppData\Local\Programs\Python\Python39\lib\site-packages\urllib3\util\ssl_.py", line 472, in _ssl_wrap_socket_impl
    return ssl_context.wrap_socket(sock, server_hostname=server_hostname)
  File "C:\Users\gallo\AppData\Local\Programs\Python\Python39\lib\ssl.py", line 500, in wrap_socket
    return self.sslsocket_class._create(
  File "C:\Users\gallo\AppData\Local\Programs\Python\Python39\lib\ssl.py", line 1040, in _create
    self.do_handshake()
  File "C:\Users\gallo\AppData\Local\Programs\Python\Python39\lib\ssl.py", line 1309, in do_handshake
    self._sslobj.do_handshake()
KeyboardInterrupt

Mon Oct 17 10:39:37 2022
Traceback (most recent call last):
  File "C:\Users\gallo\AppData\Local\Programs\Python\Python39\lib\asyncio\runners.py", line 44, in run
    return loop.run_until_complete(main)
  File "C:\Users\gallo\AppData\Local\Programs\Python\Python39\lib\asyncio\base_events.py", line 629, in run_until_complete
    self.run_forever()
  File "C:\Users\gallo\AppData\Local\Programs\Python\Python39\lib\asyncio\windows_events.py", line 316, in run_forever
    super().run_forever()
  File "C:\Users\gallo\AppData\Local\Programs\Python\Python39\lib\asyncio\base_events.py", line 596, in run_forever
    self._run_once()
  File "C:\Users\gallo\AppData\Local\Programs\Python\Python39\lib\asyncio\base_events.py", line 1854, in _run_once
    event_list = self._selector.select(timeout)
  File "C:\Users\gallo\AppData\Local\Programs\Python\Python39\lib\asyncio\windows_events.py", line 434, in select
    self._poll(timeout)
  File "C:\Users\gallo\AppData\Local\Programs\Python\Python39\lib\asyncio\windows_events.py", line 783, in _poll
    status = _overlapped.GetQueuedCompletionStatus(self._iocp, ms)
KeyboardInterrupt

During handling of the above exception, another exception occurred:

Traceback (most recent call last):
  File "c:\Users\gallo\Code\Programmi\FoxholeApi\main.py", line 94, in background_task
    await asyncio.sleep(1)
  File "C:\Users\gallo\AppData\Local\Programs\Python\Python39\lib\asyncio\tasks.py", line 649, in sleep
    return await future
asyncio.exceptions.CancelledError

Mon Oct 17 13:52:34 2022
Traceback (most recent call last):
  File "C:\Users\gallo\AppData\Local\Programs\Python\Python39\lib\asyncio\runners.py", line 44, in run
    return loop.run_until_complete(main)
  File "C:\Users\gallo\AppData\Local\Programs\Python\Python39\lib\asyncio\base_events.py", line 629, in run_until_complete
    self.run_forever()
  File "C:\Users\gallo\AppData\Local\Programs\Python\Python39\lib\asyncio\windows_events.py", line 316, in run_forever
    super().run_forever()
  File "C:\Users\gallo\AppData\Local\Programs\Python\Python39\lib\asyncio\base_events.py", line 596, in run_forever
    self._run_once()
  File "C:\Users\gallo\AppData\Local\Programs\Python\Python39\lib\asyncio\base_events.py", line 1854, in _run_once
    event_list = self._selector.select(timeout)
  File "C:\Users\gallo\AppData\Local\Programs\Python\Python39\lib\asyncio\windows_events.py", line 434, in select
    self._poll(timeout)
  File "C:\Users\gallo\AppData\Local\Programs\Python\Python39\lib\asyncio\windows_events.py", line 783, in _poll
    status = _overlapped.GetQueuedCompletionStatus(self._iocp, ms)
KeyboardInterrupt

During handling of the above exception, another exception occurred:

Traceback (most recent call last):
  File "c:\Users\gallo\Code\Programmi\FoxholeApi\main.py", line 94, in background_task
  File "C:\Users\gallo\AppData\Local\Programs\Python\Python39\lib\asyncio\tasks.py", line 649, in sleep
    return await future
asyncio.exceptions.CancelledError

Mon Oct 17 13:54:08 2022
Traceback (most recent call last):
  File "C:\Users\gallo\AppData\Local\Programs\Python\Python39\lib\asyncio\runners.py", line 44, in run
    return loop.run_until_complete(main)
  File "C:\Users\gallo\AppData\Local\Programs\Python\Python39\lib\asyncio\base_events.py", line 629, in run_until_complete
    self.run_forever()
  File "C:\Users\gallo\AppData\Local\Programs\Python\Python39\lib\asyncio\windows_events.py", line 316, in run_forever
    super().run_forever()
  File "C:\Users\gallo\AppData\Local\Programs\Python\Python39\lib\asyncio\base_events.py", line 596, in run_forever
    self._run_once()
  File "C:\Users\gallo\AppData\Local\Programs\Python\Python39\lib\asyncio\base_events.py", line 1854, in _run_once
    event_list = self._selector.select(timeout)
  File "C:\Users\gallo\AppData\Local\Programs\Python\Python39\lib\asyncio\windows_events.py", line 434, in select
    self._poll(timeout)
  File "C:\Users\gallo\AppData\Local\Programs\Python\Python39\lib\asyncio\windows_events.py", line 783, in _poll
    status = _overlapped.GetQueuedCompletionStatus(self._iocp, ms)
KeyboardInterrupt

During handling of the above exception, another exception occurred:

Traceback (most recent call last):
  File "c:\Users\gallo\Code\Programmi\FoxholeApi\main.py", line 93, in background_task
    await asyncio.sleep(1)
  File "C:\Users\gallo\AppData\Local\Programs\Python\Python39\lib\asyncio\tasks.py", line 649, in sleep
    return await future
asyncio.exceptions.CancelledError

Mon Oct 17 14:00:27 2022
Traceback (most recent call last):
  File "c:\Users\gallo\Code\Programmi\FoxholeApi\main.py", line 38, in background_task
    data = downloadData(map, 1)
  File "c:\Users\gallo\Code\Programmi\FoxholeApi\testRequest.py", line 29, in downloadData
    data = requests.get(url[1].format(map)).json()
  File "C:\Users\gallo\AppData\Local\Programs\Python\Python39\lib\site-packages\requests\api.py", line 73, in get
    return request("get", url, params=params, **kwargs)
  File "C:\Users\gallo\AppData\Local\Programs\Python\Python39\lib\site-packages\requests\api.py", line 59, in request
    return session.request(method=method, url=url, **kwargs)
  File "C:\Users\gallo\AppData\Local\Programs\Python\Python39\lib\site-packages\requests\sessions.py", line 587, in request
    resp = self.send(prep, **send_kwargs)
  File "C:\Users\gallo\AppData\Local\Programs\Python\Python39\lib\site-packages\requests\sessions.py", line 701, in send
    r = adapter.send(request, **kwargs)
  File "C:\Users\gallo\AppData\Local\Programs\Python\Python39\lib\site-packages\requests\adapters.py", line 489, in send
    resp = conn.urlopen(
  File "C:\Users\gallo\AppData\Local\Programs\Python\Python39\lib\site-packages\urllib3\connectionpool.py", line 699, in urlopen
    httplib_response = self._make_request(
  File "C:\Users\gallo\AppData\Local\Programs\Python\Python39\lib\site-packages\urllib3\connectionpool.py", line 382, in _make_request
    self._validate_conn(conn)
  File "C:\Users\gallo\AppData\Local\Programs\Python\Python39\lib\site-packages\urllib3\connectionpool.py", line 1010, in _validate_conn
    conn.connect()
  File "C:\Users\gallo\AppData\Local\Programs\Python\Python39\lib\site-packages\urllib3\connection.py", line 411, in connect
    self.sock = ssl_wrap_socket(
  File "C:\Users\gallo\AppData\Local\Programs\Python\Python39\lib\site-packages\urllib3\util\ssl_.py", line 428, in ssl_wrap_socket
    ssl_sock = _ssl_wrap_socket_impl(
  File "C:\Users\gallo\AppData\Local\Programs\Python\Python39\lib\site-packages\urllib3\util\ssl_.py", line 472, in _ssl_wrap_socket_impl
    return ssl_context.wrap_socket(sock, server_hostname=server_hostname)
  File "C:\Users\gallo\AppData\Local\Programs\Python\Python39\lib\ssl.py", line 500, in wrap_socket
    return self.sslsocket_class._create(
  File "C:\Users\gallo\AppData\Local\Programs\Python\Python39\lib\ssl.py", line 1040, in _create
    self.do_handshake()
  File "C:\Users\gallo\AppData\Local\Programs\Python\Python39\lib\ssl.py", line 1309, in do_handshake
    self._sslobj.do_handshake()
KeyboardInterrupt

Mon Oct 17 14:26:45 2022
Traceback (most recent call last):
  File "C:\Users\gallo\AppData\Local\Programs\Python\Python39\lib\asyncio\runners.py", line 44, in run
    return loop.run_until_complete(main)
  File "C:\Users\gallo\AppData\Local\Programs\Python\Python39\lib\asyncio\base_events.py", line 629, in run_until_complete
    self.run_forever()
  File "C:\Users\gallo\AppData\Local\Programs\Python\Python39\lib\asyncio\windows_events.py", line 316, in run_forever
    super().run_forever()
  File "C:\Users\gallo\AppData\Local\Programs\Python\Python39\lib\asyncio\base_events.py", line 596, in run_forever
    self._run_once()
  File "C:\Users\gallo\AppData\Local\Programs\Python\Python39\lib\asyncio\base_events.py", line 1854, in _run_once
    event_list = self._selector.select(timeout)
  File "C:\Users\gallo\AppData\Local\Programs\Python\Python39\lib\asyncio\windows_events.py", line 434, in select
    self._poll(timeout)
  File "C:\Users\gallo\AppData\Local\Programs\Python\Python39\lib\asyncio\windows_events.py", line 783, in _poll
    status = _overlapped.GetQueuedCompletionStatus(self._iocp, ms)
KeyboardInterrupt

During handling of the above exception, another exception occurred:

Traceback (most recent call last):
  File "c:\Users\gallo\Code\Programmi\FoxholeApi\main.py", line 93, in background_task
    await asyncio.sleep(1)
  File "C:\Users\gallo\AppData\Local\Programs\Python\Python39\lib\asyncio\tasks.py", line 649, in sleep
    return await future
asyncio.exceptions.CancelledError

Mon Oct 17 14:29:58 2022
Traceback (most recent call last):
  File "c:\Users\gallo\Code\Programmi\FoxholeApi\main.py", line 38, in background_task
    data = downloadData(map, 1)
  File "c:\Users\gallo\Code\Programmi\FoxholeApi\testRequest.py", line 29, in downloadData
    data = requests.get(url[1].format(map)).json()
  File "C:\Users\gallo\AppData\Local\Programs\Python\Python39\lib\site-packages\requests\api.py", line 73, in get
    return request("get", url, params=params, **kwargs)
  File "C:\Users\gallo\AppData\Local\Programs\Python\Python39\lib\site-packages\requests\api.py", line 59, in request
    return session.request(method=method, url=url, **kwargs)
  File "C:\Users\gallo\AppData\Local\Programs\Python\Python39\lib\site-packages\requests\sessions.py", line 587, in request
    resp = self.send(prep, **send_kwargs)
  File "C:\Users\gallo\AppData\Local\Programs\Python\Python39\lib\site-packages\requests\sessions.py", line 701, in send
    r = adapter.send(request, **kwargs)
  File "C:\Users\gallo\AppData\Local\Programs\Python\Python39\lib\site-packages\requests\adapters.py", line 489, in send
    resp = conn.urlopen(
  File "C:\Users\gallo\AppData\Local\Programs\Python\Python39\lib\site-packages\urllib3\connectionpool.py", line 699, in urlopen
    httplib_response = self._make_request(
  File "C:\Users\gallo\AppData\Local\Programs\Python\Python39\lib\site-packages\urllib3\connectionpool.py", line 382, in _make_request
    self._validate_conn(conn)
  File "C:\Users\gallo\AppData\Local\Programs\Python\Python39\lib\site-packages\urllib3\connectionpool.py", line 1010, in _validate_conn
    conn.connect()
  File "C:\Users\gallo\AppData\Local\Programs\Python\Python39\lib\site-packages\urllib3\connection.py", line 353, in connect
    conn = self._new_conn()
  File "C:\Users\gallo\AppData\Local\Programs\Python\Python39\lib\site-packages\urllib3\connection.py", line 169, in _new_conn
    conn = connection.create_connection(
  File "C:\Users\gallo\AppData\Local\Programs\Python\Python39\lib\site-packages\urllib3\util\connection.py", line 86, in create_connection
    sock.connect(sa)
KeyboardInterrupt

Mon Oct 17 14:34:55 2022
Traceback (most recent call last):
  File "c:\Users\gallo\Code\Programmi\FoxholeApi\main.py", line 38, in background_task
    data = downloadData(map, 1)
  File "c:\Users\gallo\Code\Programmi\FoxholeApi\testRequest.py", line 29, in downloadData
    data = requests.get(url[1].format(map)).json()
  File "C:\Users\gallo\AppData\Local\Programs\Python\Python39\lib\site-packages\requests\api.py", line 73, in get
    return request("get", url, params=params, **kwargs)
  File "C:\Users\gallo\AppData\Local\Programs\Python\Python39\lib\site-packages\requests\api.py", line 59, in request
    return session.request(method=method, url=url, **kwargs)
  File "C:\Users\gallo\AppData\Local\Programs\Python\Python39\lib\site-packages\requests\sessions.py", line 587, in request
    resp = self.send(prep, **send_kwargs)
  File "C:\Users\gallo\AppData\Local\Programs\Python\Python39\lib\site-packages\requests\sessions.py", line 701, in send
    r = adapter.send(request, **kwargs)
  File "C:\Users\gallo\AppData\Local\Programs\Python\Python39\lib\site-packages\requests\adapters.py", line 489, in send
    resp = conn.urlopen(
  File "C:\Users\gallo\AppData\Local\Programs\Python\Python39\lib\site-packages\urllib3\connectionpool.py", line 699, in urlopen
    httplib_response = self._make_request(
  File "C:\Users\gallo\AppData\Local\Programs\Python\Python39\lib\site-packages\urllib3\connectionpool.py", line 382, in _make_request
    self._validate_conn(conn)
  File "C:\Users\gallo\AppData\Local\Programs\Python\Python39\lib\site-packages\urllib3\connectionpool.py", line 1010, in _validate_conn
    conn.connect()
  File "C:\Users\gallo\AppData\Local\Programs\Python\Python39\lib\site-packages\urllib3\connection.py", line 411, in connect
    self.sock = ssl_wrap_socket(
  File "C:\Users\gallo\AppData\Local\Programs\Python\Python39\lib\site-packages\urllib3\util\ssl_.py", line 428, in ssl_wrap_socket
    ssl_sock = _ssl_wrap_socket_impl(
  File "C:\Users\gallo\AppData\Local\Programs\Python\Python39\lib\site-packages\urllib3\util\ssl_.py", line 472, in _ssl_wrap_socket_impl
    return ssl_context.wrap_socket(sock, server_hostname=server_hostname)
  File "C:\Users\gallo\AppData\Local\Programs\Python\Python39\lib\ssl.py", line 500, in wrap_socket
    return self.sslsocket_class._create(
  File "C:\Users\gallo\AppData\Local\Programs\Python\Python39\lib\ssl.py", line 1040, in _create
    self.do_handshake()
  File "C:\Users\gallo\AppData\Local\Programs\Python\Python39\lib\ssl.py", line 1309, in do_handshake
    self._sslobj.do_handshake()
KeyboardInterrupt

Mon Oct 17 14:36:35 2022
Traceback (most recent call last):
  File "C:\Users\gallo\AppData\Local\Programs\Python\Python39\lib\asyncio\runners.py", line 44, in run
    return loop.run_until_complete(main)
  File "C:\Users\gallo\AppData\Local\Programs\Python\Python39\lib\asyncio\base_events.py", line 629, in run_until_complete
    self.run_forever()
  File "C:\Users\gallo\AppData\Local\Programs\Python\Python39\lib\asyncio\windows_events.py", line 316, in run_forever
    super().run_forever()
  File "C:\Users\gallo\AppData\Local\Programs\Python\Python39\lib\asyncio\base_events.py", line 596, in run_forever
    self._run_once()
  File "C:\Users\gallo\AppData\Local\Programs\Python\Python39\lib\asyncio\base_events.py", line 1854, in _run_once
    event_list = self._selector.select(timeout)
  File "C:\Users\gallo\AppData\Local\Programs\Python\Python39\lib\asyncio\windows_events.py", line 434, in select
    self._poll(timeout)
  File "C:\Users\gallo\AppData\Local\Programs\Python\Python39\lib\asyncio\windows_events.py", line 783, in _poll
    status = _overlapped.GetQueuedCompletionStatus(self._iocp, ms)
KeyboardInterrupt

During handling of the above exception, another exception occurred:

Traceback (most recent call last):
  File "c:\Users\gallo\Code\Programmi\FoxholeApi\main.py", line 93, in background_task
    await asyncio.sleep(1)
  File "C:\Users\gallo\AppData\Local\Programs\Python\Python39\lib\asyncio\tasks.py", line 649, in sleep
    return await future
asyncio.exceptions.CancelledError

Mon Oct 17 14:38:08 2022
Traceback (most recent call last):
  File "C:\Users\gallo\AppData\Local\Programs\Python\Python39\lib\asyncio\runners.py", line 44, in run
    return loop.run_until_complete(main)
  File "C:\Users\gallo\AppData\Local\Programs\Python\Python39\lib\asyncio\base_events.py", line 629, in run_until_complete
    self.run_forever()
  File "C:\Users\gallo\AppData\Local\Programs\Python\Python39\lib\asyncio\windows_events.py", line 316, in run_forever
    super().run_forever()
  File "C:\Users\gallo\AppData\Local\Programs\Python\Python39\lib\asyncio\base_events.py", line 596, in run_forever
    self._run_once()
  File "C:\Users\gallo\AppData\Local\Programs\Python\Python39\lib\asyncio\base_events.py", line 1854, in _run_once
    event_list = self._selector.select(timeout)
  File "C:\Users\gallo\AppData\Local\Programs\Python\Python39\lib\asyncio\windows_events.py", line 434, in select
    self._poll(timeout)
  File "C:\Users\gallo\AppData\Local\Programs\Python\Python39\lib\asyncio\windows_events.py", line 783, in _poll
    status = _overlapped.GetQueuedCompletionStatus(self._iocp, ms)
KeyboardInterrupt

During handling of the above exception, another exception occurred:

Traceback (most recent call last):
  File "c:\Users\gallo\Code\Programmi\FoxholeApi\main.py", line 93, in background_task
    await asyncio.sleep(1)
  File "C:\Users\gallo\AppData\Local\Programs\Python\Python39\lib\asyncio\tasks.py", line 649, in sleep
    return await future
asyncio.exceptions.CancelledError

Mon Oct 17 14:39:08 2022
Traceback (most recent call last):
  File "C:\Users\gallo\AppData\Local\Programs\Python\Python39\lib\asyncio\runners.py", line 44, in run
    return loop.run_until_complete(main)
  File "C:\Users\gallo\AppData\Local\Programs\Python\Python39\lib\asyncio\base_events.py", line 629, in run_until_complete
    self.run_forever()
  File "C:\Users\gallo\AppData\Local\Programs\Python\Python39\lib\asyncio\windows_events.py", line 316, in run_forever
    super().run_forever()
  File "C:\Users\gallo\AppData\Local\Programs\Python\Python39\lib\asyncio\base_events.py", line 596, in run_forever
    self._run_once()
  File "C:\Users\gallo\AppData\Local\Programs\Python\Python39\lib\asyncio\base_events.py", line 1854, in _run_once
    event_list = self._selector.select(timeout)
  File "C:\Users\gallo\AppData\Local\Programs\Python\Python39\lib\asyncio\windows_events.py", line 434, in select
    self._poll(timeout)
  File "C:\Users\gallo\AppData\Local\Programs\Python\Python39\lib\asyncio\windows_events.py", line 783, in _poll
    status = _overlapped.GetQueuedCompletionStatus(self._iocp, ms)
KeyboardInterrupt

During handling of the above exception, another exception occurred:

Traceback (most recent call last):
  File "c:\Users\gallo\Code\Programmi\FoxholeApi\main.py", line 93, in background_task
    await asyncio.sleep(1)
  File "C:\Users\gallo\AppData\Local\Programs\Python\Python39\lib\asyncio\tasks.py", line 649, in sleep
    return await future
asyncio.exceptions.CancelledError

Mon Oct 17 16:28:09 2022
Traceback (most recent call last):
  File "c:\Users\gallo\Code\Programmi\FoxholeApi\main.py", line 38, in background_task
    data = downloadData(map, 1)
  File "c:\Users\gallo\Code\Programmi\FoxholeApi\testRequest.py", line 29, in downloadData
    data = requests.get(url[1].format(map)).json()
  File "C:\Users\gallo\AppData\Local\Programs\Python\Python39\lib\site-packages\requests\api.py", line 73, in get
    return request("get", url, params=params, **kwargs)
  File "C:\Users\gallo\AppData\Local\Programs\Python\Python39\lib\site-packages\requests\api.py", line 59, in request
    return session.request(method=method, url=url, **kwargs)
  File "C:\Users\gallo\AppData\Local\Programs\Python\Python39\lib\site-packages\requests\sessions.py", line 587, in request
    resp = self.send(prep, **send_kwargs)
  File "C:\Users\gallo\AppData\Local\Programs\Python\Python39\lib\site-packages\requests\sessions.py", line 701, in send
    r = adapter.send(request, **kwargs)
  File "C:\Users\gallo\AppData\Local\Programs\Python\Python39\lib\site-packages\requests\adapters.py", line 489, in send
    resp = conn.urlopen(
  File "C:\Users\gallo\AppData\Local\Programs\Python\Python39\lib\site-packages\urllib3\connectionpool.py", line 699, in urlopen
    httplib_response = self._make_request(
  File "C:\Users\gallo\AppData\Local\Programs\Python\Python39\lib\site-packages\urllib3\connectionpool.py", line 382, in _make_request
    self._validate_conn(conn)
  File "C:\Users\gallo\AppData\Local\Programs\Python\Python39\lib\site-packages\urllib3\connectionpool.py", line 1010, in _validate_conn
    conn.connect()
  File "C:\Users\gallo\AppData\Local\Programs\Python\Python39\lib\site-packages\urllib3\connection.py", line 353, in connect
    conn = self._new_conn()
  File "C:\Users\gallo\AppData\Local\Programs\Python\Python39\lib\site-packages\urllib3\connection.py", line 169, in _new_conn
    conn = connection.create_connection(
  File "C:\Users\gallo\AppData\Local\Programs\Python\Python39\lib\site-packages\urllib3\util\connection.py", line 86, in create_connection
    sock.connect(sa)
KeyboardInterrupt

Mon Oct 17 17:57:12 2022
Traceback (most recent call last):
  File "C:\Users\gallo\AppData\Local\Programs\Python\Python39\lib\asyncio\runners.py", line 44, in run
    return loop.run_until_complete(main)
  File "C:\Users\gallo\AppData\Local\Programs\Python\Python39\lib\asyncio\base_events.py", line 629, in run_until_complete
    self.run_forever()
  File "C:\Users\gallo\AppData\Local\Programs\Python\Python39\lib\asyncio\windows_events.py", line 316, in run_forever
    super().run_forever()
  File "C:\Users\gallo\AppData\Local\Programs\Python\Python39\lib\asyncio\base_events.py", line 596, in run_forever
    self._run_once()
  File "C:\Users\gallo\AppData\Local\Programs\Python\Python39\lib\asyncio\base_events.py", line 1854, in _run_once
    event_list = self._selector.select(timeout)
  File "C:\Users\gallo\AppData\Local\Programs\Python\Python39\lib\asyncio\windows_events.py", line 434, in select
    self._poll(timeout)
  File "C:\Users\gallo\AppData\Local\Programs\Python\Python39\lib\asyncio\windows_events.py", line 783, in _poll
    status = _overlapped.GetQueuedCompletionStatus(self._iocp, ms)
KeyboardInterrupt

During handling of the above exception, another exception occurred:

Traceback (most recent call last):
  File "c:\Users\gallo\Code\Programmi\FoxholeApi\main.py", line 93, in background_task
    await asyncio.sleep(1)
  File "C:\Users\gallo\AppData\Local\Programs\Python\Python39\lib\asyncio\tasks.py", line 649, in sleep
    return await future
asyncio.exceptions.CancelledError

Mon Oct 17 20:04:10 2022
Traceback (most recent call last):
  File "C:\Users\gallo\AppData\Local\Programs\Python\Python39\lib\asyncio\runners.py", line 44, in run
    return loop.run_until_complete(main)
  File "C:\Users\gallo\AppData\Local\Programs\Python\Python39\lib\asyncio\base_events.py", line 629, in run_until_complete
    self.run_forever()
  File "C:\Users\gallo\AppData\Local\Programs\Python\Python39\lib\asyncio\windows_events.py", line 316, in run_forever
    super().run_forever()
  File "C:\Users\gallo\AppData\Local\Programs\Python\Python39\lib\asyncio\base_events.py", line 596, in run_forever
    self._run_once()
  File "C:\Users\gallo\AppData\Local\Programs\Python\Python39\lib\asyncio\base_events.py", line 1854, in _run_once
    event_list = self._selector.select(timeout)
  File "C:\Users\gallo\AppData\Local\Programs\Python\Python39\lib\asyncio\windows_events.py", line 434, in select
    self._poll(timeout)
  File "C:\Users\gallo\AppData\Local\Programs\Python\Python39\lib\asyncio\windows_events.py", line 783, in _poll
    status = _overlapped.GetQueuedCompletionStatus(self._iocp, ms)
KeyboardInterrupt

During handling of the above exception, another exception occurred:

Traceback (most recent call last):
  File "c:\Users\gallo\Code\Programmi\FoxholeApi\main.py", line 93, in background_task
    await asyncio.sleep(1)
  File "C:\Users\gallo\AppData\Local\Programs\Python\Python39\lib\asyncio\tasks.py", line 649, in sleep
    return await future
asyncio.exceptions.CancelledError

